[2024-06-11 05:41:02,614] {taskinstance.py:826} INFO - Dependencies all met for <TaskInstance: ELT_to_Data_Warehouse.process_latest_files 2024-06-11T05:39:15.217293+00:00 [queued]>
[2024-06-11 05:41:02,620] {taskinstance.py:826} INFO - Dependencies all met for <TaskInstance: ELT_to_Data_Warehouse.process_latest_files 2024-06-11T05:39:15.217293+00:00 [queued]>
[2024-06-11 05:41:02,620] {taskinstance.py:1017} INFO - 
--------------------------------------------------------------------------------
[2024-06-11 05:41:02,620] {taskinstance.py:1018} INFO - Starting attempt 2 of 2
[2024-06-11 05:41:02,620] {taskinstance.py:1019} INFO - 
--------------------------------------------------------------------------------
[2024-06-11 05:41:02,632] {taskinstance.py:1038} INFO - Executing <Task(PythonOperator): process_latest_files> on 2024-06-11T05:39:15.217293+00:00
[2024-06-11 05:41:02,635] {standard_task_runner.py:51} INFO - Started process 16483 to run task
[2024-06-11 05:41:02,641] {standard_task_runner.py:75} INFO - Running: ['airflow', 'tasks', 'run', 'ELT_to_Data_Warehouse', 'process_latest_files', '2024-06-11T05:39:15.217293+00:00', '--job-id', '71', '--pool', 'default_pool', '--raw', '--subdir', 'DAGS_FOLDER/elt_to_dw.py', '--cfg-path', '/tmp/tmp8um5capw']
[2024-06-11 05:41:02,642] {standard_task_runner.py:76} INFO - Job 71: Subtask process_latest_files
[2024-06-11 05:41:02,676] {logging_mixin.py:103} INFO - Running <TaskInstance: ELT_to_Data_Warehouse.process_latest_files 2024-06-11T05:39:15.217293+00:00 [running]> on host etl.us-central1-a.c.data-engineering-stock.internal
[2024-06-11 05:41:02,694] {taskinstance.py:1230} INFO - Exporting the following env vars:
AIRFLOW_CTX_DAG_OWNER=airflow
AIRFLOW_CTX_DAG_ID=ELT_to_Data_Warehouse
AIRFLOW_CTX_TASK_ID=process_latest_files
AIRFLOW_CTX_EXECUTION_DATE=2024-06-11T05:39:15.217293+00:00
AIRFLOW_CTX_DAG_RUN_ID=manual__2024-06-11T05:39:15.217293+00:00
[2024-06-11 05:41:02,697] {elt_to_dw.py:82} INFO - Files pulled from XCom: Uploaded /home/anhcu/Project/Stock_project/elt/data/completed/load_api_ohlcs_to_dl/crawl_ohlcs_2024_06_10.parquet to /user/anhcu/datalake/ohlcs on HDFS
Uploaded /home/anhcu/Project/Stock_project/elt/data/completed/load_api_news_to_dl/crawl_news_2024_06_10.parquet to /user/anhcu/datalake/news on HDFS
Uploaded /home/anhcu/Project/Stock_project/elt/data/completed/load_db_to_dl/load_db_to_dl_2024_06_11.parquet to /user/anhcu/datalake/companies on HDFS
/user/anhcu/datalake/ohlcs/crawl_ohlcs_2024_06_10.parquet
/user/anhcu/datalake/news/crawl_news_2024_06_10.parquet
/user/anhcu/datalake/companies/load_db_to_dl_2024_06_11.parquet


[2024-06-11 05:41:13,604] {taskinstance.py:1396} ERROR - An error occurred while calling o27.parquet.
: java.net.ConnectException: Your endpoint configuration is wrong; For more details see:  http://wiki.apache.org/hadoop/UnsetHostnameOrPort
	at java.base/jdk.internal.reflect.NativeConstructorAccessorImpl.newInstance0(Native Method)
	at java.base/jdk.internal.reflect.NativeConstructorAccessorImpl.newInstance(NativeConstructorAccessorImpl.java:62)
	at java.base/jdk.internal.reflect.DelegatingConstructorAccessorImpl.newInstance(DelegatingConstructorAccessorImpl.java:45)
	at java.base/java.lang.reflect.Constructor.newInstance(Constructor.java:490)
	at org.apache.hadoop.net.NetUtils.wrapWithMessage(NetUtils.java:913)
	at org.apache.hadoop.net.NetUtils.wrapException(NetUtils.java:824)
	at org.apache.hadoop.ipc.Client.getRpcResponse(Client.java:1616)
	at org.apache.hadoop.ipc.Client.call(Client.java:1558)
	at org.apache.hadoop.ipc.Client.call(Client.java:1455)
	at org.apache.hadoop.ipc.ProtobufRpcEngine2$Invoker.invoke(ProtobufRpcEngine2.java:242)
	at org.apache.hadoop.ipc.ProtobufRpcEngine2$Invoker.invoke(ProtobufRpcEngine2.java:129)
	at com.sun.proxy.$Proxy35.getFileInfo(Unknown Source)
	at org.apache.hadoop.hdfs.protocolPB.ClientNamenodeProtocolTranslatorPB.getFileInfo(ClientNamenodeProtocolTranslatorPB.java:965)
	at java.base/jdk.internal.reflect.NativeMethodAccessorImpl.invoke0(Native Method)
	at java.base/jdk.internal.reflect.NativeMethodAccessorImpl.invoke(NativeMethodAccessorImpl.java:62)
	at java.base/jdk.internal.reflect.DelegatingMethodAccessorImpl.invoke(DelegatingMethodAccessorImpl.java:43)
	at java.base/java.lang.reflect.Method.invoke(Method.java:566)
	at org.apache.hadoop.io.retry.RetryInvocationHandler.invokeMethod(RetryInvocationHandler.java:422)
	at org.apache.hadoop.io.retry.RetryInvocationHandler$Call.invokeMethod(RetryInvocationHandler.java:165)
	at org.apache.hadoop.io.retry.RetryInvocationHandler$Call.invoke(RetryInvocationHandler.java:157)
	at org.apache.hadoop.io.retry.RetryInvocationHandler$Call.invokeOnce(RetryInvocationHandler.java:95)
	at org.apache.hadoop.io.retry.RetryInvocationHandler.invoke(RetryInvocationHandler.java:359)
	at com.sun.proxy.$Proxy36.getFileInfo(Unknown Source)
	at org.apache.hadoop.hdfs.DFSClient.getFileInfo(DFSClient.java:1739)
	at org.apache.hadoop.hdfs.DistributedFileSystem$29.doCall(DistributedFileSystem.java:1753)
	at org.apache.hadoop.hdfs.DistributedFileSystem$29.doCall(DistributedFileSystem.java:1750)
	at org.apache.hadoop.fs.FileSystemLinkResolver.resolve(FileSystemLinkResolver.java:81)
	at org.apache.hadoop.hdfs.DistributedFileSystem.getFileStatus(DistributedFileSystem.java:1765)
	at org.apache.hadoop.fs.FileSystem.exists(FileSystem.java:1760)
	at org.apache.spark.sql.execution.datasources.DataSource$.$anonfun$checkAndGlobPathIfNecessary$4(DataSource.scala:756)
	at org.apache.spark.sql.execution.datasources.DataSource$.$anonfun$checkAndGlobPathIfNecessary$4$adapted(DataSource.scala:754)
	at org.apache.spark.util.ThreadUtils$.$anonfun$parmap$2(ThreadUtils.scala:384)
	at scala.concurrent.Future$.$anonfun$apply$1(Future.scala:659)
	at scala.util.Success.$anonfun$map$1(Try.scala:255)
	at scala.util.Success.map(Try.scala:213)
	at scala.concurrent.Future.$anonfun$map$1(Future.scala:292)
	at scala.concurrent.impl.Promise.liftedTree1$1(Promise.scala:33)
	at scala.concurrent.impl.Promise.$anonfun$transform$1(Promise.scala:33)
	at scala.concurrent.impl.CallbackRunnable.run(Promise.scala:64)
	at java.base/java.util.concurrent.ForkJoinTask$RunnableExecuteAction.exec(ForkJoinTask.java:1426)
	at java.base/java.util.concurrent.ForkJoinTask.doExec(ForkJoinTask.java:290)
	at java.base/java.util.concurrent.ForkJoinPool$WorkQueue.topLevelExec(ForkJoinPool.java:1020)
	at java.base/java.util.concurrent.ForkJoinPool.scan(ForkJoinPool.java:1656)
	at java.base/java.util.concurrent.ForkJoinPool.runWorker(ForkJoinPool.java:1594)
	at java.base/java.util.concurrent.ForkJoinWorkerThread.run(ForkJoinWorkerThread.java:183)
Caused by: java.net.ConnectException: Connection refused
	at java.base/sun.nio.ch.SocketChannelImpl.checkConnect(Native Method)
	at java.base/sun.nio.ch.SocketChannelImpl.finishConnect(SocketChannelImpl.java:777)
	at org.apache.hadoop.net.SocketIOWithTimeout.connect(SocketIOWithTimeout.java:205)
	at org.apache.hadoop.net.NetUtils.connect(NetUtils.java:586)
	at org.apache.hadoop.ipc.Client$Connection.setupConnection(Client.java:711)
	at org.apache.hadoop.ipc.Client$Connection.setupIOstreams(Client.java:833)
	at org.apache.hadoop.ipc.Client$Connection.access$3800(Client.java:414)
	at org.apache.hadoop.ipc.Client.getConnection(Client.java:1677)
	at org.apache.hadoop.ipc.Client.call(Client.java:1502)
	... 37 more
Traceback (most recent call last):
  File "/home/anhcu/Project/Stock_project/airflow_venv/lib/python3.8/site-packages/airflow/models/taskinstance.py", line 1086, in _run_raw_task
    self._prepare_and_execute_task_with_callbacks(context, task)
  File "/home/anhcu/Project/Stock_project/airflow_venv/lib/python3.8/site-packages/airflow/models/taskinstance.py", line 1260, in _prepare_and_execute_task_with_callbacks
    result = self._execute_task(context, task_copy)
  File "/home/anhcu/Project/Stock_project/airflow_venv/lib/python3.8/site-packages/airflow/models/taskinstance.py", line 1300, in _execute_task
    result = task_copy.execute(context=context)
  File "/home/anhcu/Project/Stock_project/airflow_venv/lib/python3.8/site-packages/airflow/operators/python.py", line 117, in execute
    return_value = self.execute_callable()
  File "/home/anhcu/Project/Stock_project/airflow_venv/lib/python3.8/site-packages/airflow/operators/python.py", line 128, in execute_callable
    return self.python_callable(*self.op_args, **self.op_kwargs)
  File "/home/anhcu/Project/Stock_project/airflow/dags/elt_to_dw.py", line 90, in process_latest_files
    process_ohlcs(file_path)
  File "/home/anhcu/Project/Stock_project/airflow/dags/elt_to_dw.py", line 98, in process_ohlcs
    transform_to_datawarehouse_2.process(hdfs_path)
  File "/home/anhcu/Project/Stock_project/elt/scripts/transform/transform_to_datawarehouse_2.py", line 15, in process
    df_spark = spark.read.parquet(parquet_file_path)
  File "/usr/local/spark/python/pyspark/sql/readwriter.py", line 544, in parquet
    return self._df(self._jreader.parquet(_to_seq(self._spark._sc, paths)))
  File "/home/anhcu/.local/lib/python3.8/site-packages/py4j/java_gateway.py", line 1322, in __call__
    return_value = get_return_value(
  File "/usr/local/spark/python/pyspark/errors/exceptions/captured.py", line 179, in deco
    return f(*a, **kw)
  File "/home/anhcu/.local/lib/python3.8/site-packages/py4j/protocol.py", line 326, in get_return_value
    raise Py4JJavaError(
py4j.protocol.Py4JJavaError: An error occurred while calling o27.parquet.
: java.net.ConnectException: Your endpoint configuration is wrong; For more details see:  http://wiki.apache.org/hadoop/UnsetHostnameOrPort
	at java.base/jdk.internal.reflect.NativeConstructorAccessorImpl.newInstance0(Native Method)
	at java.base/jdk.internal.reflect.NativeConstructorAccessorImpl.newInstance(NativeConstructorAccessorImpl.java:62)
	at java.base/jdk.internal.reflect.DelegatingConstructorAccessorImpl.newInstance(DelegatingConstructorAccessorImpl.java:45)
	at java.base/java.lang.reflect.Constructor.newInstance(Constructor.java:490)
	at org.apache.hadoop.net.NetUtils.wrapWithMessage(NetUtils.java:913)
	at org.apache.hadoop.net.NetUtils.wrapException(NetUtils.java:824)
	at org.apache.hadoop.ipc.Client.getRpcResponse(Client.java:1616)
	at org.apache.hadoop.ipc.Client.call(Client.java:1558)
	at org.apache.hadoop.ipc.Client.call(Client.java:1455)
	at org.apache.hadoop.ipc.ProtobufRpcEngine2$Invoker.invoke(ProtobufRpcEngine2.java:242)
	at org.apache.hadoop.ipc.ProtobufRpcEngine2$Invoker.invoke(ProtobufRpcEngine2.java:129)
	at com.sun.proxy.$Proxy35.getFileInfo(Unknown Source)
	at org.apache.hadoop.hdfs.protocolPB.ClientNamenodeProtocolTranslatorPB.getFileInfo(ClientNamenodeProtocolTranslatorPB.java:965)
	at java.base/jdk.internal.reflect.NativeMethodAccessorImpl.invoke0(Native Method)
	at java.base/jdk.internal.reflect.NativeMethodAccessorImpl.invoke(NativeMethodAccessorImpl.java:62)
	at java.base/jdk.internal.reflect.DelegatingMethodAccessorImpl.invoke(DelegatingMethodAccessorImpl.java:43)
	at java.base/java.lang.reflect.Method.invoke(Method.java:566)
	at org.apache.hadoop.io.retry.RetryInvocationHandler.invokeMethod(RetryInvocationHandler.java:422)
	at org.apache.hadoop.io.retry.RetryInvocationHandler$Call.invokeMethod(RetryInvocationHandler.java:165)
	at org.apache.hadoop.io.retry.RetryInvocationHandler$Call.invoke(RetryInvocationHandler.java:157)
	at org.apache.hadoop.io.retry.RetryInvocationHandler$Call.invokeOnce(RetryInvocationHandler.java:95)
	at org.apache.hadoop.io.retry.RetryInvocationHandler.invoke(RetryInvocationHandler.java:359)
	at com.sun.proxy.$Proxy36.getFileInfo(Unknown Source)
	at org.apache.hadoop.hdfs.DFSClient.getFileInfo(DFSClient.java:1739)
	at org.apache.hadoop.hdfs.DistributedFileSystem$29.doCall(DistributedFileSystem.java:1753)
	at org.apache.hadoop.hdfs.DistributedFileSystem$29.doCall(DistributedFileSystem.java:1750)
	at org.apache.hadoop.fs.FileSystemLinkResolver.resolve(FileSystemLinkResolver.java:81)
	at org.apache.hadoop.hdfs.DistributedFileSystem.getFileStatus(DistributedFileSystem.java:1765)
	at org.apache.hadoop.fs.FileSystem.exists(FileSystem.java:1760)
	at org.apache.spark.sql.execution.datasources.DataSource$.$anonfun$checkAndGlobPathIfNecessary$4(DataSource.scala:756)
	at org.apache.spark.sql.execution.datasources.DataSource$.$anonfun$checkAndGlobPathIfNecessary$4$adapted(DataSource.scala:754)
	at org.apache.spark.util.ThreadUtils$.$anonfun$parmap$2(ThreadUtils.scala:384)
	at scala.concurrent.Future$.$anonfun$apply$1(Future.scala:659)
	at scala.util.Success.$anonfun$map$1(Try.scala:255)
	at scala.util.Success.map(Try.scala:213)
	at scala.concurrent.Future.$anonfun$map$1(Future.scala:292)
	at scala.concurrent.impl.Promise.liftedTree1$1(Promise.scala:33)
	at scala.concurrent.impl.Promise.$anonfun$transform$1(Promise.scala:33)
	at scala.concurrent.impl.CallbackRunnable.run(Promise.scala:64)
	at java.base/java.util.concurrent.ForkJoinTask$RunnableExecuteAction.exec(ForkJoinTask.java:1426)
	at java.base/java.util.concurrent.ForkJoinTask.doExec(ForkJoinTask.java:290)
	at java.base/java.util.concurrent.ForkJoinPool$WorkQueue.topLevelExec(ForkJoinPool.java:1020)
	at java.base/java.util.concurrent.ForkJoinPool.scan(ForkJoinPool.java:1656)
	at java.base/java.util.concurrent.ForkJoinPool.runWorker(ForkJoinPool.java:1594)
	at java.base/java.util.concurrent.ForkJoinWorkerThread.run(ForkJoinWorkerThread.java:183)
Caused by: java.net.ConnectException: Connection refused
	at java.base/sun.nio.ch.SocketChannelImpl.checkConnect(Native Method)
	at java.base/sun.nio.ch.SocketChannelImpl.finishConnect(SocketChannelImpl.java:777)
	at org.apache.hadoop.net.SocketIOWithTimeout.connect(SocketIOWithTimeout.java:205)
	at org.apache.hadoop.net.NetUtils.connect(NetUtils.java:586)
	at org.apache.hadoop.ipc.Client$Connection.setupConnection(Client.java:711)
	at org.apache.hadoop.ipc.Client$Connection.setupIOstreams(Client.java:833)
	at org.apache.hadoop.ipc.Client$Connection.access$3800(Client.java:414)
	at org.apache.hadoop.ipc.Client.getConnection(Client.java:1677)
	at org.apache.hadoop.ipc.Client.call(Client.java:1502)
	... 37 more

[2024-06-11 05:41:13,611] {taskinstance.py:1433} INFO - Marking task as FAILED. dag_id=ELT_to_Data_Warehouse, task_id=process_latest_files, execution_date=20240611T053915, start_date=20240611T054102, end_date=20240611T054113
[2024-06-11 05:41:13,656] {local_task_job.py:118} INFO - Task exited with return code 1
